Workbook

Sheet TRACK_STD
I1: =SUBTOTAL(9,I3:I513) -> 28001 | U1: =SUBTOTAL(9,U3:U513) -> 33646.915 | V1: =SUBTOTAL(9,V3:V513) -> 1278.5828 | W1: =SUBTOTAL(9,W3:W513) -> 1682.3458
A2: PO Received Date | B2: Shipment Date | C2: Matalan Product PO# | D2: Supplier Name | E2: Factory Name | F2: Packaging Supplier Name | G2: eBiz Customer Reference # | H2: eBiz Sales Order # | I2: Carton QTY | J2: Carton Style | K2: FLUTE | L2: Carton Selection | M2: Length(mm) | N2: Width(mm) | O2: Height(mm) | P2: L | Q2: W | R2: Area(sqm) | S2: Carton's Unit Price (CNY,EXW w/VAT) | T2: Final Price, CNY/CTN | U2: Total Amount | V2: 4% for PACD | W2: Rebates for Matalan (Singles=5%) | X2: NOTE
A3: 46235 | B3: 46237 | D3: KDS IDR Ltd. | E3: KDS IDR Ltd. | F3: Transworld Packaging (BD) Ltd. | G3: B0496925 | H3: 7124457 | I3: 176 | J3: Standard Carton-Singles | K3: BC-Flute | L3: C1 | M3: {=IF(L3="",0,_xlfn.SWITCH(L3,"A1",495,"A2",495,"A3",495,"Custom",0,595))} -> 595 | N3: {=IF(L3="",0,_xlfn.SWITCH(L3,"C1",325,"C2",325,"C3",325,"D1",380,"D2",380,"D3",380,"Custom",0,285))} -> 325 | O3: =IF(L3="",0,_xlfn.SWITCH(L3,"A1",375,"B1",375,"C1",375,"D1",375,"A2",310,"B2",310,"C2",310,"D2",310,"Custom",0,260)) -> 375 | P3: =IFERROR(IF(OR(M3=0,N3=0),0,(M3+N3)*2+11),0) -> 1851 | Q3: =IFERROR(IF(OR(N3=0,O3=0),0,(N3+O3)-16),0) -> 684 | R3: =P3*Q3/1000000 -> 1.266084 | S3: =IFERROR(VLOOKUP(L3,'Carton Sizes Chart'!$A$4:$E$15,5,FALSE),0) -> 1.22 | T3: =S3 -> 1.22 | U3: =I3*T3 -> 214.72 | V3: =((T3*I3)-W3)*4% -> 8.15936 | W3: =S3*I3*5% -> 10.736
A4: 46235 | B4: 46237 | D4: KDS IDR Ltd. | E4: KDS IDR Ltd. | F4: Transworld Packaging (BD) Ltd. | G4: G0516728 | H4: 7125716 | I4: 131 | J4: Standard Carton-Singles | K4: BC-Flute | L4: D3 | M4: {=IF(L4="",0,_xlfn.SWITCH(L4,"A1",495,"A2",495,"A3",495,"Custom",0,595))} -> 595 | N4: {=IF(L4="",0,_xlfn.SWITCH(L4,"C1",325,"C2",325,"C3",325,"D1",380,"D2",380,"D3",380,"Custom",0,285))} -> 380 | O4: =IF(L4="",0,_xlfn.SWITCH(L4,"A1",375,"B1",375,"C1",375,"D1",375,"A2",310,"B2",310,"C2",310,"D2",310,"Custom",0,260)) -> 260 | P4: =IFERROR(IF(OR(M4=0,N4=0),0,(M4+N4)*2+11),0) -> 1961 | Q4: =IFERROR(IF(OR(N4=0,O4=0),0,(N4+O4)-16),0) -> 624 | R4: =P4*Q4/1000000 -> 1.223664 | S4: =IFERROR(VLOOKUP(L4,'Carton Sizes Chart'!$A$4:$E$15,5,FALSE),0) -> 1.18 | T4: =S4 -> 1.18 | U4: =I4*T4 -> 154.58 | V4: =((T4*I4)-W4)*4% -> 5.87404 | W4: =S4*I4*5% -> 7.729
A5: 46233 | B5: 46235 | D5: Appollo Fashion Ltd. | E5: Appollo Knit Wear (BD) Ltd. | F5: Transworld Packaging (BD) Ltd. | G5: ASW26TG41_900+73+74+75+7 | H5: 7126382 | I5: 43 | J5: Standard Carton-Singles | K5: BC-Flute | L5: C2 | M5: {=IF(L5="",0,_xlfn.SWITCH(L5,"A1",495,"A2",495,"A3",495,"Custom",0,595))} -> 595 | N5: {=IF(L5="",0,_xlfn.SWITCH(L5,"C1",325,"C2",325,"C3",325,"D1",380,"D2",380,"D3",380,"Custom",0,285))} -> 325 | O5: =IF(L5="",0,_xlfn.SWITCH(L5,"A1",375,"B1",375,"C1",375,"D1",375,"A2",310,"B2",310,"C2",310,"D2",310,"Custom",0,260)) -> 310 | P5: =IFERROR(IF(OR(M5=0,N5=0),0,(M5+N5)*2+11),0) -> 1851 | Q5: =IFERROR(IF(OR(N5=0,O5=0),0,(N5+O5)-16),0) -> 619 | R5: =P5*Q5/1000000 -> 1.145769 | S5: =IFERROR(VLOOKUP(L5,'Carton Sizes Chart'!$A$4:$E$15,5,FALSE),0) -> 1.1 | T5: =S5 -> 1.1 | U5: =I5*T5 -> 47.3 | V5: =((T5*I5)-W5)*4% -> 1.7974 | W5: =S5*I5*5% -> 2.365
A6: 46233 | B6: 46235 | D6: Appollo Fashion Ltd. | E6: Appollo Knit Wear (BD) Ltd. | F6: Transworld Packaging (BD) Ltd. | G6: ASW26TG41_900+73+74+75+7 | H6: 7126382 | I6: 62 | J6: Standard Carton-Singles | K6: BC-Flute | L6: D2 | M6: {=IF(L6="",0,_xlfn.SWITCH(L6,"A1",495,"A2",495,"A3",495,"Custom",0,595))} -> 595 | N6: {=IF(L6="",0,_xlfn.SWITCH(L6,"C1",325,"C2",325,"C3",325,"D1",380,"D2",380,"D3",380,"Custom",0,285))} -> 380 | O6: =IF(L6="",0,_xlfn.SWITCH(L6,"A1",375,"B1",375,"C1",375,"D1",375,"A2",310,"B2",310,"C2",310,"D2",310,"Custom",0,260)) -> 310 | P6: =IFERROR(IF(OR(M6=0,N6=0),0,(M6+N6)*2+11),0) -> 1961 | Q6: =IFERROR(IF(OR(N6=0,O6=0),0,(N6+O6)-16),0) -> 674 | R6: =P6*Q6/1000000 -> 1.321714 | S6: =IFERROR(VLOOKUP(L6,'Carton Sizes Chart'!$A$4:$E$15,5,FALSE),0) -> 1.27 | T6: =S6 -> 1.27 | U6: =I6*T6 -> 78.74 | V6: =((T6*I6)-W6)*4% -> 2.99212 | W6: =S6*I6*5% -> 3.937
A7: 46233 | B7: 46235 | D7: Lariz Fashion Ltd | E7: Lariz Fashion Ltd | F7: Transworld Packaging (BD) Ltd. | G7: C0998545 | H7: 7126761 | I7: 130 | J7: Standard Carton-Singles | K7: BC-Flute | L7: C2 | M7: {=IF(L7="",0,_xlfn.SWITCH(L7,"A1",495,"A2",495,"A3",495,"Custom",0,595))} -> 595 | N7: {=IF(L7="",0,_xlfn.SWITCH(L7,"C1",325,"C2",325,"C3",325,"D1",380,"D2",380,"D3",380,"Custom",0,285))} -> 325 | O7: =IF(L7="",0,_xlfn.SWITCH(L7,"A1",375,"B1",375,"C1",375,"D1",375,"A2",310,"B2",310,"C2",310,"D2",310,"Custom",0,260)) -> 310 | P7: =IFERROR(IF(OR(M7=0,N7=0),0,(M7+N7)*2+11),0) -> 1851 | Q7: =IFERROR(IF(OR(N7=0,O7=0),0,(N7+O7)-16),0) -> 619 | R7: =P7*Q7/1000000 -> 1.145769 | S7: =IFERROR(VLOOKUP(L7,'Carton Sizes Chart'!$A$4:$E$15,5,FALSE),0) -> 1.1 | T7: =S7 -> 1.1 | U7: =I7*T7 -> 143 | V7: =((T7*I7)-W7)*4% -> 5.434 | W7: =S7*I7*5% -> 7.15
A8: 46235 | B8: 46237 | D8: KDS IDR Ltd. | E8: KDS IDR Ltd. | F8: Transworld Packaging (BD) Ltd. | G8: B0496737 | H8: 7127600 | I8: 37 | J8: Standard Carton-Singles | K8: BC-Flute | L8: D1 | M8: {=IF(L8="",0,_xlfn.SWITCH(L8,"A1",495,"A2",495,"A3",495,"Custom",0,595))} -> 595 | N8: {=IF(L8="",0,_xlfn.SWITCH(L8,"C1",325,"C2",325,"C3",325,"D1",380,"D2",380,"D3",380,"Custom",0,285))} -> 380 | O8: =IF(L8="",0,_xlfn.SWITCH(L8,"A1",375,"B1",375,"C1",375,"D1",375,"A2",310,"B2",310,"C2",310,"D2",310,"Custom",0,260)) -> 375 | P8: =IFERROR(IF(OR(M8=0,N8=0),0,(M8+N8)*2+11),0) -> 1961 | Q8: =IFERROR(IF(OR(N8=0,O8=0),0,(N8+O8)-16),0) -> 739 | R8: =P8*Q8/1000000 -> 1.449179 | S8: =IFERROR(VLOOKUP(L8,'Carton Sizes Chart'!$A$4:$E$15,5,FALSE),0) -> 1.39 | T8: =S8 -> 1.39 | U8: =I8*T8 -> 51.43 | V8: =((T8*I8)-W8)*4% -> 1.95434 | W8: =S8*I8*5% -> 2.5715
A9: 46235 | B9: 46237 | D9: KDS IDR Ltd. | E9: KDS IDR Ltd. | F9: Transworld Packaging (BD) Ltd. | G9: G0516728 | H9: 7127890 | I9: 122 | J9: Standard Carton-Singles | K9: BC-Flute | L9: D3 | M9: {=IF(L9="",0,_xlfn.SWITCH(L9,"A1",495,"A2",495,"A3",495,"Custom",0,595))} -> 595 | N9: {=IF(L9="",0,_xlfn.SWITCH(L9,"C1",325,"C2",325,"C3",325,"D1",380,"D2",380,"D3",380,"Custom",0,285))} -> 380 | O9: =IF(L9="",0,_xlfn.SWITCH(L9,"A1",375,"B1",375,"C1",375,"D1",375,"A2",310,"B2",310,"C2",310,"D2",310,"Custom",0,260)) -> 260 | P9: =IFERROR(IF(OR(M9=0,N9=0),0,(M9+N9)*2+11),0) -> 1961 | Q9: =IFERROR(IF(OR(N9=0,O9=0),0,(N9+O9)-16),0) -> 624 | R9: =P9*Q9/1000000 -> 1.223664 | S9: =IFERROR(VLOOKUP(L9,'Carton Sizes Chart'!$A$4:$E$15,5,FALSE),0) -> 1.18 | T9: =S9 -> 1.18 | U9: =I9*T9 -> 143.96 | V9: =((T9*I9)-W9)*4% -> 5.47048 | W9: =S9*I9*5% -> 7.198
A10: 46236 | B10: 46238 | D10: CONCORD VENTURES EXPORTS LLC | E10: Dhaka Garments & Washing Ltd. | F10: Transworld Packaging (BD) Ltd. | G10: Relaxed Fit | H10: 7127958 | I10: 260 | J10: Standard Carton-Singles | K10: BC-Flute | L10: C1 | M10: {=IF(L10="",0,_xlfn.SWITCH(L10,"A1",495,"A2",495,"A3",495,"Custom",0,595))} -> 595 | N10: {=IF(L10="",0,_xlfn.SWITCH(L10,"C1",325,"C2",325,"C3",325,"D1",380,"D2",380,"D3",380,"Custom",0,285))} -> 325 | O10: =IF(L10="",0,_xlfn.SWITCH(L10,"A1",375,"B1",375,"C1",375,"D1",375,"A2",310,"B2",310,"C2",310,"D2",310,"Custom",0,260)) -> 375 | P10: =IFERROR(IF(OR(M10=0,N10=0),0,(M10+N10)*2+11),0) -> 1851 | Q10: =IFERROR(IF(OR(N10=0,O10=0),0,(N10+O10)-16),0) -> 684 | R10: =P10*Q10/1000000 -> 1.266084 | S10: =IFERROR(VLOOKUP(L10,'Carton Sizes Chart'!$A$4:$E$15,5,FALSE),0) -> 1.22 | T10: =S10 -> 1.22 | U10: =I10*T10 -> 317.2 | V10: =((T10*I10)-W10)*4% -> 12.0536 | W10: =S10*I10*5% -> 15.86
A11: 46240 | B11: 46243 | D11: KDS IDR Ltd. | E11: KDS IDR Ltd. | F11: Transworld Packaging (BD) Ltd. | G11: G0516742 | H11: 7130655 | I11: 156 | J11: Standard Carton-Singles | K11: BC-Flute | L11: D1 | M11: {=IF(L11="",0,_xlfn.SWITCH(L11,"A1",495,"A2",495,"A3",495,"Custom",0,595))} -> 595 | N11: {=IF(L11="",0,_xlfn.SWITCH(L11,"C1",325,"C2",325,"C3",325,"D1",380,"D2",380,"D3",380,"Custom",0,285))} -> 380 | O11: =IF(L11="",0,_xlfn.SWITCH(L11,"A1",375,"B1",375,"C1",375,"D1",375,"A2",310,"B2",310,"C2",310,"D2",310,"Custom",0,260)) -> 375 | P11: =IFERROR(IF(OR(M11=0,N11=0),0,(M11+N11)*2+11),0) -> 1961 | Q11: =IFERROR(IF(OR(N11=0,O11=0),0,(N11+O11)-16),0) -> 739 | R11: =P11*Q11/1000000 -> 1.449179 | S11: =IFERROR(VLOOKUP(L11,'Carton Sizes Chart'!$A$4:$E$15,5,FALSE),0) -> 1.39 | T11: =S11 -> 1.39 | U11: =I11*T11 -> 216.84 | V11: =((T11*I11)-W11)*4% -> 8.23992 | W11: =S11*I11*5% -> 10.842
A12: 46245 | B12: 46246 | D12: Grand Apparels Design | E12: Virtual Bottom | F12: Transworld Packaging (BD) Ltd. | G12: F3033105 | H12: 7133412 | I12: 30 | J12: Standard Carton-Singles | K12: BC-Flute | L12: D1 | M12: {=IF(L12="",0,_xlfn.SWITCH(L12,"A1",495,"A2",495,"A3",495,"Custom",0,595))} -> 595 | N12: {=IF(L12="",0,_xlfn.SWITCH(L12,"C1",325,"C2",325,"C3",325,"D1",380,"D2",380,"D3",380,"Custom",0,285))} -> 380 | O12: =IF(L12="",0,_xlfn.SWITCH(L12,"A1",375,"B1",375,"C1",375,"D1",375,"A2",310,"B2",310,"C2",310,"D2",310,"Custom",0,260)) -> 375 | P12: =IFERROR(IF(OR(M12=0,N12=0),0,(M12+N12)*2+11),0) -> 1961 | Q12: =IFERROR(IF(OR(N12=0,O12=0),0,(N12+O12)-16),0) -> 739 | R12: =P12*Q12/1000000 -> 1.449179 | S12: =IFERROR(VLOOKUP(L12,'Carton Sizes Chart'!$A$4:$E$15,5,FALSE),0) -> 1.39 | T12: =S12 -> 1.39 | U12: =I12*T12 -> 41.7 | V12: =((T12*I12)-W12)*4% -> 1.5846 | W12: =S12*I12*5% -> 2.085
A13: 46246 | B13: 46247 | D13: KDS IDR Ltd. | E13: KDS IDR Ltd. | F13: Transworld Packaging (BD) Ltd. | G13: G0516742 | H13: 7134357 | I13: 111 | J13: Standard Carton-Singles | K13: BC-Flute | L13: D1 | M13: {=IF(L13="",0,_xlfn.SWITCH(L13,"A1",495,"A2",495,"A3",495,"Custom",0,595))} -> 595 | N13: {=IF(L13="",0,_xlfn.SWITCH(L13,"C1",325,"C2",325,"C3",325,"D1",380,"D2",380,"D3",380,"Custom",0,285))} -> 380 | O13: =IF(L13="",0,_xlfn.SWITCH(L13,"A1",375,"B1",375,"C1",375,"D1",375,"A2",310,"B2",310,"C2",310,"D2",310,"Custom",0,260)) -> 375 | P13: =IFERROR(IF(OR(M13=0,N13=0),0,(M13+N13)*2+11),0) -> 1961 | Q13: =IFERROR(IF(OR(N13=0,O13=0),0,(N13+O13)-16),0) -> 739 | R13: =P13*Q13/1000000 -> 1.449179 | S13: =IFERROR(VLOOKUP(L13,'Carton Sizes Chart'!$A$4:$E$15,5,FALSE),0) -> 1.39 | T13: =S13 -> 1.39 | U13: =I13*T13 -> 154.29 | V13: =((T13*I13)-W13)*4% -> 5.86302 | W13: =S13*I13*5% -> 7.7145
A14: 46247 | B14: 46249 | D14: Grand Apparels Design | E14: Virtual Bottom | F14: Transworld Packaging (BD) Ltd. | G14: F3033032 | H14: 7134783 | I14: 15 | J14: Standard Carton-Singles | K14: BC-Flute | L14: D1 | M14: {=IF(L14="",0,_xlfn.SWITCH(L14,"A1",495,"A2",495,"A3",495,"Custom",0,595))} -> 595 | N14: {=IF(L14="",0,_xlfn.SWITCH(L14,"C1",325,"C2",325,"C3",325,"D1",380,"D2",380,"D3",380,"Custom",0,285))} -> 380 | O14: =IF(L14="",0,_xlfn.SWITCH(L14,"A1",375,"B1",375,"C1",375,"D1",375,"A2",310,"B2",310,"C2",310,"D2",310,"Custom",0,260)) -> 375 | P14: =IFERROR(IF(OR(M14=0,N14=0),0,(M14+N14)*2+11),0) -> 1961 | Q14: =IFERROR(IF(OR(N14=0,O14=0),0,(N14+O14)-16),0) -> 739 | R14: =P14*Q14/1000000 -> 1.449179 | S14: =IFERROR(VLOOKUP(L14,'Carton Sizes Chart'!$A$4:$E$15,5,FALSE),0) -> 1.39 | T14: =S14 -> 1.39 | U14: =I14*T14 -> 20.85 | V14: =((T14*I14)-W14)*4% -> 0.7923 | W14: =S14*I14*5% -> 1.0425
... A57: 46264 | B57: 46265 | D57: KDS IDR Ltd. | E57: KDS IDR Ltd. | F57: Transworld Packaging (BD) Ltd. | G57: C1018995 | H57: 7144726 | I57: 1219 | J57: Standard Carton-Singles | K57: BC-Flute | L57: B1 | M57: {=IF(L57="",0,_xlfn.SWITCH(L57,"A1",495,"A2",495,"A3",495,"Custom",0,595))} -> 595 | N57: {=IF(L57="",0,_xlfn.SWITCH(L57,"C1",325,"C2",325,"C3",325,"D1",380,"D2",380,"D3",380,"Custom",0,285))} -> 285 | O57: =IF(L57="",0,_xlfn.SWITCH(L57,"A1",375,"B1",375,"C1",375,"D1",375,"A2",310,"B2",310,"C2",310,"D2",310,"Custom",0,260)) -> 375 | P57: =IFERROR(IF(OR(M57=0,N57=0),0,(M57+N57)*2+11),0) -> 1771 | Q57: =IFERROR(IF(OR(N57=0,O57=0),0,(N57+O57)-16),0) -> 644 | R57: =P57*Q57/1000000 -> 1.140524 | S57: =IFERROR(VLOOKUP(L57,'Carton Sizes Chart'!$A$4:$E$15,5,FALSE),0) -> 1.1 | T57: =S57 -> 1.1 | U57: =I57*T57 -> 1340.9 | V57: =((T57*I57)-W57)*4% -> 50.9542 | W57: =S57*I57*5% -> 67.045
A58: 46232 | B58: 46235 | D58: Crown Exclusive Wears Ltd. | E58: Crown Exclusive Wears Ltd. | F58: Uniglory Packaging Industries Ltd. | G58: CHW26KN076 | H58: 7125575 | I58: 221 | J58: Standard Carton-Singles | K58: BC-Flute | L58: Custom | M58: 750 | N58: 560 | O58: 320 | P58: =IFERROR(IF(OR(M58=0,N58=0),0,(M58+N58)*2+11),0) -> 2631 | Q58: =IFERROR(IF(OR(N58=0,O58=0),0,(N58+O58)-16),0) -> 864 | R58: =P58*Q58/1000000 -> 2.273184 | S58: =IF(L58="Custom", R58*'[1]RFQ_Matalan Carton'!$M$40, IFERROR(VLOOKUP(L58,'[1]Carton Sizes Chart'!$A$4:$E$15,5,FALSE),0)) -> 2.1822566 | T58: =S58 -> 2.1822566 | U58: =I58*T58 -> 482.27872 | V58: =((T58*I58)-W58)*4% -> 18.326591 | W58: =S58*I58*5% -> 24.113936
A59: 46232 | B59: 46235 | D59: Crown Exclusive Wears Ltd. | E59: Crown Exclusive Wears Ltd. | F59: Uniglory Packaging Industries Ltd. | G59: CHW26KN076 | H59: 7125575 | I59: 329 | J59: Standard Carton-Singles | K59: BC-Flute | L59: Custom | M59: 770 | N59: 610 | O59: 320 | P59: =IFERROR(IF(OR(M59=0,N59=0),0,(M59+N59)*2+11),0) -> 2771 | Q59: =IFERROR(IF(OR(N59=0,O59=0),0,(N59+O59)-16),0) -> 914 | R59: =P59*Q59/1000000 -> 2.532694 | S59: =IF(L59="Custom", R59*'[1]RFQ_Matalan Carton'!$M$40, IFERROR(VLOOKUP(L59,'[1]Carton Sizes Chart'!$A$4:$E$15,5,FALSE),0)) -> 2.4313862 | T59: =S59 -> 2.4313862 | U59: =I59*T59 -> 799.92607 | V59: =((T59*I59)-W59)*4% -> 30.397191 | W59: =S59*I59*5% -> 39.996304
A60: 46232 | B60: 46235 | D60: Crown Exclusive Wears Ltd. | E60: Crown Exclusive Wears Ltd. | F60: Uniglory Packaging Industries Ltd. | G60: CHW26KN076 | H60: 7125575 | I60: 204 | J60: Standard Carton-Singles | K60: BC-Flute | L60: Custom | M60: 790 | N60: 660 | O60: 320 | P60: =IFERROR(IF(OR(M60=0,N60=0),0,(M60+N60)*2+11),0) -> 2911 | Q60: =IFERROR(IF(OR(N60=0,O60=0),0,(N60+O60)-16),0) -> 964 | R60: =P60*Q60/1000000 -> 2.806204 | S60: =IF(L60="Custom", R60*'[1]RFQ_Matalan Carton'!$M$40, IFERROR(VLOOKUP(L60,'[1]Carton Sizes Chart'!$A$4:$E$15,5,FALSE),0)) -> 2.6939558 | T60: =S60 -> 2.6939558 | U60: =I60*T60 -> 549.56699 | V60: =((T60*I60)-W60)*4% -> 20.883546 | W60: =S60*I60*5% -> 27.47835
A61: 46232 | B61: 46235 | D61: Crown Exclusive Wears Ltd. | E61: Crown Exclusive Wears Ltd. | F61: Uniglory Packaging Industries Ltd. | G61: CHW26KN076 | H61: 7125575 | I61: 71 | J61: Standard Carton-Singles | K61: BC-Flute | L61: Custom | M61: 810 | N61: 710 | O61: 320 | P61: =IFERROR(IF(OR(M61=0,N61=0),0,(M61+N61)*2+11),0) -> 3051 | Q61: =IFERROR(IF(OR(N61=0,O61=0),0,(N61+O61)-16),0) -> 1014 | R61: =P61*Q61/1000000 -> 3.093714 | S61: =IF(L61="Custom", R61*'[1]RFQ_Matalan Carton'!$M$40, IFERROR(VLOOKUP(L61,'[1]Carton Sizes Chart'!$A$4:$E$15,5,FALSE),0)) -> 2.9699654 | T61: =S61 -> 2.9699654 | U61: =I61*T61 -> 210.86755 | V61: =((T61*I61)-W61)*4% -> 8.0129668 | W61: =S61*I61*5% -> 10.543377
A62: 46232 | B62: 46235 | D62: Crown Exclusive Wears Ltd. | E62: Crown Exclusive Wears Ltd. | F62: Uniglory Packaging Industries Ltd. | G62: CHW26KN076 | H62: 7125575 | I62: 555 | J62: Standard Carton-Singles | K62: BC-Flute | L62: Custom | M62: 800 | N62: 620 | O62: 240 | P62: =IFERROR(IF(OR(M62=0,N62=0),0,(M62+N62)*2+11),0) -> 2851 | Q62: =IFERROR(IF(OR(N62=0,O62=0),0,(N62+O62)-16),0) -> 844 | R62: =P62*Q62/1000000 -> 2.406244 | S62: =IF(L62="Custom", R62*'[1]RFQ_Matalan Carton'!$M$40, IFERROR(VLOOKUP(L62,'[1]Carton Sizes Chart'!$A$4:$E$15,5,FALSE),0)) -> 2.3099942 | T62: =S62 -> 2.3099942 | U62: =I62*T62 -> 1282.0468 | V62: =((T62*I62)-W62)*4% -> 48.717779 | W62: =S62*I62*5% -> 64.10234
A63: 46232 | B63: 46235 | D63: Design ARC Asia | E63: Confidance Knitwear Ltd. | F63: Uniglory Packaging Industries Ltd. | G63: OB010 B0501578 | H63: 7126198 | I63: 179 | J63: Standard Carton-Singles | K63: BC-Flute | L63: C3 | M63: {=IF(L63="",0,_xlfn.SWITCH(L63,"A1",495,"A2",495,"A3",495,"Custom",0,595))} -> 595 | N63: {=IF(L63="",0,_xlfn.SWITCH(L63,"C1",325,"C2",325,"C3",325,"D1",380,"D2",380,"D3",380,"Custom",0,285))} -> 325 | O63: =IF(L63="",0,_xlfn.SWITCH(L63,"A1",375,"B1",375,"C1",375,"D1",375,"A2",310,"B2",310,"C2",310,"D2",310,"Custom",0,260)) -> 260 | P63: =IFERROR(IF(OR(M63=0,N63=0),0,(M63+N63)*2+11),0) -> 1851 | Q63: =IFERROR(IF(OR(N63=0,O63=0),0,(N63+O63)-16),0) -> 569 | R63: =P63*Q63/1000000 -> 1.053219 | S63: =IFERROR(VLOOKUP(L63,'Carton Sizes Chart'!$A$4:$E$15,5,FALSE),0) -> 1.02 | T63: =S63 -> 1.02 | U63: =I63*T63 -> 182.58 | V63: =((T63*I63)-W63)*4% -> 6.93804 | W63: =S63*I63*5% -> 9.129
A64: 46232 | B64: 46235 | D64: Design ARC Asia | E64: Confidance Knitwear Ltd. | F64: Uniglory Packaging Industries Ltd. | G64: OB010 B0501578 | H64: 7126198 | I64: 57 | J64: Standard Carton-Singles | K64: BC-Flute | L64: C2 | M64: {=IF(L64="",0,_xlfn.SWITCH(L64,"A1",495,"A2",495,"A3",495,"Custom",0,595))} -> 595 | N64: {=IF(L64="",0,_xlfn.SWITCH(L64,"C1",325,"C2",325,"C3",325,"D1",380,"D2",380,"D3",380,"Custom",0,285))} -> 325 | O64: =IF(L64="",0,_xlfn.SWITCH(L64,"A1",375,"B1",375,"C1",375,"D1",375,"A2",310,"B2",310,"C2",310,"D2",310,"Custom",0,260)) -> 310 | P64: =IFERROR(IF(OR(M64=0,N64=0),0,(M64+N64)*2+11),0) -> 1851 | Q64: =IFERROR(IF(OR(N64=0,O64=0),0,(N64+O64)-16),0) -> 619 | R64: =P64*Q64/1000000 -> 1.145769 | S64: =IFERROR(VLOOKUP(L64,'Carton Sizes Chart'!$A$4:$E$15,5,FALSE),0) -> 1.1 | T64: =S64 -> 1.1 | U64: =I64*T64 -> 62.7 | V64: =((T64*I64)-W64)*4% -> 2.3826 | W64: =S64*I64*5% -> 3.135
A65: 46236 | B65: 46236 | D65: Crown Exclusive Wears Ltd. | E65: Crown Exclusive Wears Ltd. | F65: Uniglory Packaging Industries Ltd. | G65: CHW26KN084 | H65: 7127907 | I65: 40 | J65: Standard Carton-Singles | K65: BC-Flute | L65: Custom | M65: 620 | N65: 420 | O65: 250 | P65: =IFERROR(IF(OR(M65=0,N65=0),0,(M65+N65)*2+11),0) -> 2091 | Q65: =IFERROR(IF(OR(N65=0,O65=0),0,(N65+O65)-16),0) -> 654 | R65: =P65*Q65/1000000 -> 1.367514 | S65: =IF(L65="Custom", R65*'[1]RFQ_Matalan Carton'!$M$40, IFERROR(VLOOKUP(L65,'[1]Carton Sizes Chart'!$A$4:$E$15,5,FALSE),0)) -> 1.3128134 | T65: =S65 -> 1.3128134 | U65: =I65*T65 -> 52.512538 | V65: =((T65*I65)-W65)*4% -> 1.9954764 | W65: =S65*I65*5% -> 2.6256269
A66: 46236 | B66: 46240 | D66: Design ARC Asia | E66: Confidance Knitwear Ltd. | F66: Uniglory Packaging Industries Ltd. | G66: TG03 | H66: 7128054 | I66: 148 | J66: Standard Carton-Singles | K66: BC-Flute | L66: C1 | M66: {=IF(L66="",0,_xlfn.SWITCH(L66,"A1",495,"A2",495,"A3",495,"Custom",0,595))} -> 595 | N66: {=IF(L66="",0,_xlfn.SWITCH(L66,"C1",325,"C2",325,"C3",325,"D1",380,"D2",380,"D3",380,"Custom",0,285))} -> 325 | O66: =IF(L66="",0,_xlfn.SWITCH(L66,"A1",375,"B1",375,"C1",375,"D1",375,"A2",310,"B2",310,"C2",310,"D2",310,"Custom",0,260)) -> 375 | P66: =IFERROR(IF(OR(M66=0,N66=0),0,(M66+N66)*2+11),0) -> 1851 | Q66: =IFERROR(IF(OR(N66=0,O66=0),0,(N66+O66)-16),0) -> 684 | R66: =P66*Q66/1000000 -> 1.266084 | S66: =IFERROR(VLOOKUP(L66,'Carton Sizes Chart'!$A$4:$E$15,5,FALSE),0) -> 1.22 | T66: =S66 -> 1.22 | U66: =I66*T66 -> 180.56 | V66: =((T66*I66)-W66)*4% -> 6.86128 | W66: =S66*I66*5% -> 9.028
A67: 46238 | B67: 46243 | D67: Design ARC Asia | E67: Confidance Knitwear Ltd. | F67: Uniglory Packaging Industries Ltd. | G67: TG01 | H67: 7129094 | I67: 44 | J67: Standard Carton-Singles | K67: BC-Flute | L67: C2 | M67: {=IF(L67="",0,_xlfn.SWITCH(L67,"A1",495,"A2",495,"A3",495,"Custom",0,595))} -> 595 | N67: {=IF(L67="",0,_xlfn.SWITCH(L67,"C1",325,"C2",325,"C3",325,"D1",380,"D2",380,"D3",380,"Custom",0,285))} -> 325 | O67: =IF(L67="",0,_xlfn.SWITCH(L67,"A1",375,"B1",375,"C1",375,"D1",375,"A2",310,"B2",310,"C2",310,"D2",310,"Custom",0,260)) -> 310 | P67: =IFERROR(IF(OR(M67=0,N67=0),0,(M67+N67)*2+11),0) -> 1851 | Q67: =IFERROR(IF(OR(N67=0,O67=0),0,(N67+O67)-16),0) -> 619 | R67: =P67*Q67/1000000 -> 1.145769 | S67: =IFERROR(VLOOKUP(L67,'Carton Sizes Chart'!$A$4:$E$15,5,FALSE),0) -> 1.1 | T67: =S67 -> 1.1 | U67: =I67*T67 -> 48.4 | V67: =((T67*I67)-W67)*4% -> 1.8392 | W67: =S67*I67*5% -> 2.42
A68: 46240 | B68: 46243 | D68: Design ARC Asia | E68: Confidance Knitwear Ltd. | F68: Uniglory Packaging Industries Ltd. | G68: OB01 | H68: 7130506 | I68: 158 | J68: Standard Carton-Singles | K68: BC-Flute | L68: C1 | M68: {=IF(L68="",0,_xlfn.SWITCH(L68,"A1",495,"A2",495,"A3",495,"Custom",0,595))} -> 595 | N68: {=IF(L68="",0,_xlfn.SWITCH(L68,"C1",325,"C2",325,"C3",325,"D1",380,"D2",380,"D3",380,"Custom",0,285))} -> 325 | O68: =IF(L68="",0,_xlfn.SWITCH(L68,"A1",375,"B1",375,"C1",375,"D1",375,"A2",310,"B2",310,"C2",310,"D2",310,"Custom",0,260)) -> 375 | P68: =IFERROR(IF(OR(M68=0,N68=0),0,(M68+N68)*2+11),0) -> 1851 | Q68: =IFERROR(IF(OR(N68=0,O68=0),0,(N68+O68)-16),0) -> 684 | R68: =P68*Q68/1000000 -> 1.266084 | S68: =IFERROR(VLOOKUP(L68,'Carton Sizes Chart'!$A$4:$E$15,5,FALSE),0) -> 1.22 | T68: =S68 -> 1.22 | U68: =I68*T68 -> 192.76 | V68: =((T68*I68)-W68)*4% -> 7.32488 | W68: =S68*I68*5% -> 9.638
A69: 46243 | B69: 46244 | D69: Design ARC Asia | E69: AR-Tex Composite Ltd. | F69: Uniglory Packaging Industries Ltd. | G69: F476035 | H69: 7132064 | I69: 1600 | J69: Standard Carton-Singles | K69: BC-Flute | L69: B1 | M69: {=IF(L69="",0,_xlfn.SWITCH(L69,"A1",495,"A2",495,"A3",495,"Custom",0,595))} -> 595 | N69: {=IF(L69="",0,_xlfn.SWITCH(L69,"C1",325,"C2",325,"C3",325,"D1",380,"D2",380,"D3",380,"Custom",0,285))} -> 285 | O69: =IF(L69="",0,_xlfn.SWITCH(L69,"A1",375,"B1",375,"C1",375,"D1",375,"A2",310,"B2",310,"C2",310,"D2",310,"Custom",0,260)) -> 375 | P69: =IFERROR(IF(OR(M69=0,N69=0),0,(M69+N69)*2+11),0) -> 1771 | Q69: =IFERROR(IF(OR(N69=0,O69=0),0,(N69+O69)-16),0) -> 644 | R69: =P69*Q69/1000000 -> 1.140524 | S69: =IFERROR(VLOOKUP(L69,'Carton Sizes Chart'!$A$4:$E$15,5,FALSE),0) -> 1.1 | T69: =S69 -> 1.1 | U69: =I69*T69 -> 1760 | V69: =((T69*I69)-W69)*4% -> 66.88 | W69: =S69*I69*5% -> 88
A70: 46246 | B70: 46247 | D70: KESKAN FZC | E70: H.B Knittex Ltd. | F70: Uniglory Packaging Industries Ltd. | G70: GCW26SE19AB | H70: 7132988 | I70: 21 | J70: Standard Carton-Singles | K70: BC-Flute | L70: C3 | M70: {=IF(L70="",0,_xlfn.SWITCH(L70,"A1",495,"A2",495,"A3",495,"Custom",0,595))} -> 595 | N70: {=IF(L70="",0,_xlfn.SWITCH(L70,"C1",325,"C2",325,"C3",325,"D1",380,"D2",380,"D3",380,"Custom",0,285))} -> 325 | O70: =IF(L70="",0,_xlfn.SWITCH(L70,"A1",375,"B1",375,"C1",375,"D1",375,"A2",310,"B2",310,"C2",310,"D2",310,"Custom",0,260)) -> 260 | P70: =IFERROR(IF(OR(M70=0,N70=0),0,(M70+N70)*2+11),0) -> 1851 | Q70: =IFERROR(IF(OR(N70=0,O70=0),0,(N70+O70)-16),0) -> 569 | R70: =P70*Q70/1000000 -> 1.053219 | S70: =IFERROR(VLOOKUP(L70,'Carton Sizes Chart'!$A$4:$E$15,5,FALSE),0) -> 1.02 | T70: =S70 -> 1.02 | U70: =I70*T70 -> 21.42 | V70: =((T70*I70)-W70)*4% -> 0.81396 | W70: =S70*I70*5% -> 1.071 | X70: Revise
A71: 46246 | B71: 46247 | D71: KESKAN FZC | E71: H.B Knittex Ltd. | F71: Uniglory Packaging Industries Ltd. | G71: GCW26SE19AB | H71: 7132988 | I71: 75 | J71: Standard Carton-Singles | K71: BC-Flute | L71: D3 | M71: {=IF(L71="",0,_xlfn.SWITCH(L71,"A1",495,"A2",495,"A3",495,"Custom",0,595))} -> 595 | N71: {=IF(L71="",0,_xlfn.SWITCH(L71,"C1",325,"C2",325,"C3",325,"D1",380,"D2",380,"D3",380,"Custom",0,285))} -> 380 | O71: =IF(L71="",0,_xlfn.SWITCH(L71,"A1",375,"B1",375,"C1",375,"D1",375,"A2",310,"B2",310,"C2",310,"D2",310,"Custom",0,260)) -> 260 | P71: =IFERROR(IF(OR(M71=0,N71=0),0,(M71+N71)*2+11),0) -> 1961 | Q71: =IFERROR(IF(OR(N71=0,O71=0),0,(N71+O71)-16),0) -> 624 | R71: =P71*Q71/1000000 -> 1.223664 | S71: =IFERROR(VLOOKUP(L71,'Carton Sizes Chart'!$A$4:$E$15,5,FALSE),0) -> 1.18 | T71: =S71 -> 1.18 | U71: =I71*T71 -> 88.5 | V71: =((T71*I71)-W71)*4% -> 3.363 | W71: =S71*I71*5% -> 4.425
A72: 46246 | B72: 46247 | D72: KESKAN FZC | E72: Desh Garments Ltd. | F72: Uniglory Packaging Industries Ltd. | G72: GCW26SH02AB | H72: 7134301 | I72: 15 | J72: Standard Carton-Singles | K72: BC-Flute | L72: C3 | M72: {=IF(L72="",0,_xlfn.SWITCH(L72,"A1",495,"A2",495,"A3",495,"Custom",0,595))} -> 595 | N72: {=IF(L72="",0,_xlfn.SWITCH(L72,"C1",325,"C2",325,"C3",325,"D1",380,"D2",380,"D3",380,"Custom",0,285))} -> 325 | O72: =IF(L72="",0,_xlfn.SWITCH(L72,"A1",375,"B1",375,"C1",375,"D1",375,"A2",310,"B2",310,"C2",310,"D2",310,"Custom",0,260)) -> 260 | P72: =IFERROR(IF(OR(M72=0,N72=0),0,(M72+N72)*2+11),0) -> 1851 | Q72: =IFERROR(IF(OR(N72=0,O72=0),0,(N72+O72)-16),0) -> 569 | R72: =P72*Q72/1000000 -> 1.053219 | S72: =IFERROR(VLOOKUP(L72,'Carton Sizes Chart'!$A$4:$E$15,5,FALSE),0) -> 1.02 | T72: =S72 -> 1.02 | U72: =I72*T72 -> 15.3 | V72: =((T72*I72)-W72)*4% -> 0.5814 | W72: =S72*I72*5% -> 0.765
A73: 46246 | B73: 46247 | D73: KESKAN FZC | E73: Desh Garments Ltd. | F73: Uniglory Packaging Industries Ltd. | G73: GCW26SH02AB | H73: 7134301 | I73: 62 | J73: Standard Carton-Singles | K73: BC-Flute | L73: D3 | M73: {=IF(L73="",0,_xlfn.SWITCH(L73,"A1",495,"A2",495,"A3",495,"Custom",0,595))} -> 595 | N73: {=IF(L73="",0,_xlfn.SWITCH(L73,"C1",325,"C2",325,"C3",325,"D1",380,"D2",380,"D3",380,"Custom",0,285))} -> 380 | O73: =IF(L73="",0,_xlfn.SWITCH(L73,"A1",375,"B1",375,"C1",375,"D1",375,"A2",310,"B2",310,"C2",310,"D2",310,"Custom",0,260)) -> 260 | P73: =IFERROR(IF(OR(M73=0,N73=0),0,(M73+N73)*2+11),0) -> 1961 | Q73: =IFERROR(IF(OR(N73=0,O73=0),0,(N73+O73)-16),0) -> 624 | R73: =P73*Q73/1000000 -> 1.223664 | S73: =IFERROR(VLOOKUP(L73,'Carton Sizes Chart'!$A$4:$E$15,5,FALSE),0) -> 1.18 | T73: =S73 -> 1.18 | U73: =I73*T73 -> 73.16 | V73: =((T73*I73)-W73)*4% -> 2.78008 | W73: =S73*I73*5% -> 3.658
A74: 46247 | B74: 46250 | D74: Design ARC Asia | E74: Confidance Knitwear Ltd. | F74: Uniglory Packaging Industries Ltd. | G74: TDS02 | H74: 7135089 | I74: 15 | J74: Standard Carton-Singles | K74: BC-Flute | L74: C2 | M74: {=IF(L74="",0,_xlfn.SWITCH(L74,"A1",495,"A2",495,"A3",495,"Custom",0,595))} -> 595 | N74: {=IF(L74="",0,_xlfn.SWITCH(L74,"C1",325,"C2",325,"C3",325,"D1",380,"D2",380,"D3",380,"Custom",0,285))} -> 325 | O74: =IF(L74="",0,_xlfn.SWITCH(L74,"A1",375,"B1",375,"C1",375,"D1",375,"A2",310,"B2",310,"C2",310,"D2",310,"Custom",0,260)) -> 310 | P74: =IFERROR(IF(OR(M74=0,N74=0),0,(M74+N74)*2+11),0) -> 1851 | Q74: =IFERROR(IF(OR(N74=0,O74=0),0,(N74+O74)-16),0) -> 619 | R74: =P74*Q74/1000000 -> 1.145769 | S74: =IFERROR(VLOOKUP(L74,'Carton Sizes Chart'!$A$4:$E$15,5,FALSE),0) -> 1.1 | T74: =S74 -> 1.1 | U74: =I74*T74 -> 16.5 | V74: =((T74*I74)-W74)*4% -> 0.627 | W74: =S74*I74*5% -> 0.825
A75: 46247 | B75: 46250 | D75: Design ARC Asia | E75: Confidance Knitwear Ltd. | F75: Uniglory Packaging Industries Ltd. | G75: TDS02 | H75: 7135089 | I75: 47 | J75: Standard Carton-Singles | K75: BC-Flute | L75: C1 | M75: {=IF(L75="",0,_xlfn.SWITCH(L75,"A1",495,"A2",495,"A3",495,"Custom",0,595))} -> 595 | N75: {=IF(L75="",0,_xlfn.SWITCH(L75,"C1",325,"C2",325,"C3",325,"D1",380,"D2",380,"D3",380,"Custom",0,285))} -> 325 | O75: =IF(L75="",0,_xlfn.SWITCH(L75,"A1",375,"B1",375,"C1",375,"D1",375,"A2",310,"B2",310,"C2",310,"D2",310,"Custom",0,260)) -> 375 | P75: =IFERROR(IF(OR(M75=0,N75=0),0,(M75+N75)*2+11),0) -> 1851 | Q75: =IFERROR(IF(OR(N75=0,O75=0),0,(N75+O75)-16),0) -> 684 | R75: =P75*Q75/1000000 -> 1.266084 | S75: =IFERROR(VLOOKUP(L75,'Carton Sizes Chart'!$A$4:$E$15,5,FALSE),0) -> 1.22 | T75: =S75 -> 1.22 | U75: =I75*T75 -> 57.34 | V75: =((T75*I75)-W75)*4% -> 2.17892 | W75: =S75*I75*5% -> 2.867
A76: 46247 | B76: 46250 | D76: Design ARC Asia | E76: Confidance Knitwear Ltd. | F76: Uniglory Packaging Industries Ltd. | G76: TDS02 | H76: 7135089 | I76: 31 | J76: Standard Carton-Singles | K76: BC-Flute | L76: D1 | M76: {=IF(L76="",0,_xlfn.SWITCH(L76,"A1",495,"A2",495,"A3",495,"Custom",0,595))} -> 595 | N76: {=IF(L76="",0,_xlfn.SWITCH(L76,"C1",325,"C2",325,"C3",325,"D1",380,"D2",380,"D3",380,"Custom",0,285))} -> 380 | O76: =IF(L76="",0,_xlfn.SWITCH(L76,"A1",375,"B1",375,"C1",375,"D1",375,"A2",310,"B2",310,"C2",310,"D2",310,"Custom",0,260)) -> 375 | P76: =IFERROR(IF(OR(M76=0,N76=0),0,(M76+N76)*2+11),0) -> 1961 | Q76: =IFERROR(IF(OR(N76=0,O76=0),0,(N76+O76)-16),0) -> 739 | R76: =P76*Q76/1000000 -> 1.449179 | S76: =IFERROR(VLOOKUP(L76,'Carton Sizes Chart'!$A$4:$E$15,5,FALSE),0) -> 1.39 | T76: =S76 -> 1.39 | U76: =I76*T76 -> 43.09 | V76: =((T76*I76)-W76)*4% -> 1.63742 | W76: =S76*I76*5% -> 2.1545
A77: 46247 | B77: 46249 | D77: Design ARC Asia | E77: Confidance Knitwear Ltd. | F77: Uniglory Packaging Industries Ltd. | G77: BTS02 | H77: 7135275 | I77: 41 | J77: Standard Carton-Singles | K77: BC-Flute | L77: C1 | M77: {=IF(L77="",0,_xlfn.SWITCH(L77,"A1",495,"A2",495,"A3",495,"Custom",0,595))} -> 595 | N77: {=IF(L77="",0,_xlfn.SWITCH(L77,"C1",325,"C2",325,"C3",325,"D1",380,"D2",380,"D3",380,"Custom",0,285))} -> 325 | O77: =IF(L77="",0,_xlfn.SWITCH(L77,"A1",375,"B1",375,"C1",375,"D1",375,"A2",310,"B2",310,"C2",310,"D2",310,"Custom",0,260)) -> 375 | P77: =IFERROR(IF(OR(M77=0,N77=0),0,(M77+N77)*2+11),0) -> 1851 | Q77: =IFERROR(IF(OR(N77=0,O77=0),0,(N77+O77)-16),0) -> 684 | R77: =P77*Q77/1000000 -> 1.266084 | S77: =IFERROR(VLOOKUP(L77,'Carton Sizes Chart'!$A$4:$E$15,5,FALSE),0) -> 1.22 | T77: =S77 -> 1.22 | U77: =I77*T77 -> 50.02 | V77: =((T77*I77)-W77)*4% -> 1.90076 | W77: =S77*I77*5% -> 2.501
A78: 46247 | B78: 46249 | D78: Design ARC Asia | E78: Confidance Knitwear Ltd. | F78: Uniglory Packaging Industries Ltd. | G78: BTS02 | H78: 7135275 | I78: 17 | J78: Standard Carton-Singles | K78: BC-Flute | L78: D1 | M78: {=IF(L78="",0,_xlfn.SWITCH(L78,"A1",495,"A2",495,"A3",495,"Custom",0,595))} -> 595 | N78: {=IF(L78="",0,_xlfn.SWITCH(L78,"C1",325,"C2",325,"C3",325,"D1",380,"D2",380,"D3",380,"Custom",0,285))} -> 380 | O78: =IF(L78="",0,_xlfn.SWITCH(L78,"A1",375,"B1",375,"C1",375,"D1",375,"A2",310,"B2",310,"C2",310,"D2",310,"Custom",0,260)) -> 375 | P78: =IFERROR(IF(OR(M78=0,N78=0),0,(M78+N78)*2+11),0) -> 1961 | Q78: =IFERROR(IF(OR(N78=0,O78=0),0,(N78+O78)-16),0) -> 739 | R78: =P78*Q78/1000000 -> 1.449179 | S78: =IFERROR(VLOOKUP(L78,'Carton Sizes Chart'!$A$4:$E$15,5,FALSE),0) -> 1.39 | T78: =S78 -> 1.39 | U78: =I78*T78 -> 23.63 | V78: =((T78*I78)-W78)*4% -> 0.89794 | W78: =S78*I78*5% -> 1.1815
A79: 46249 | B79: 46254 | D79: Design ARC Asia | E79: Confidance Knitwear Ltd. | F79: Uniglory Packaging Industries Ltd. | G79: BTS02 | H79: 7136111 | I79: 70 | J79: Standard Carton-Singles | K79: BC-Flute | L79: C1 | M79: {=IF(L79="",0,_xlfn.SWITCH(L79,"A1",495,"A2",495,"A3",495,"Custom",0,595))} -> 595 | N79: {=IF(L79="",0,_xlfn.SWITCH(L79,"C1",325,"C2",325,"C3",325,"D1",380,"D2",380,"D3",380,"Custom",0,285))} -> 325 | O79: =IF(L79="",0,_xlfn.SWITCH(L79,"A1",375,"B1",375,"C1",375,"D1",375,"A2",310,"B2",310,"C2",310,"D2",310,"Custom",0,260)) -> 375 | P79: =IFERROR(IF(OR(M79=0,N79=0),0,(M79+N79)*2+11),0) -> 1851 | Q79: =IFERROR(IF(OR(N79=0,O79=0),0,(N79+O79)-16),0) -> 684 | R79: =P79*Q79/1000000 -> 1.266084 | S79: =IFERROR(VLOOKUP(L79,'Carton Sizes Chart'!$A$4:$E$15,5,FALSE),0) -> 1.22 | T79: =S79 -> 1.22 | U79: =I79*T79 -> 85.4 | V79: =((T79*I79)-W79)*4% -> 3.2452 | W79: =S79*I79*5% -> 4.27
A80: 46249 | B80: 46254 | D80: Design ARC Asia | E80: Confidance Knitwear Ltd. | F80: Uniglory Packaging Industries Ltd. | G80: BTS02 | H80: 7136111 | I80: 27 | J80: Standard Carton-Singles | K80: BC-Flute | L80: D1 | M80: {=IF(L80="",0,_xlfn.SWITCH(L80,"A1",495,"A2",495,"A3",495,"Custom",0,595))} -> 595 | N80: {=IF(L80="",0,_xlfn.SWITCH(L80,"C1",325,"C2",325,"C3",325,"D1",380,"D2",380,"D3",380,"Custom",0,285))} -> 380 | O80: =IF(L80="",0,_xlfn.SWITCH(L80,"A1",375,"B1",375,"C1",375,"D1",375,"A2",310,"B2",310,"C2",310,"D2",310,"Custom",0,260)) -> 375 | P80: =IFERROR(IF(OR(M80=0,N80=0),0,(M80+N80)*2+11),0) -> 1961 | Q80: =IFERROR(IF(OR(N80=0,O80=0),0,(N80+O80)-16),0) -> 739 | R80: =P80*Q80/1000000 -> 1.449179 | S80: =IFERROR(VLOOKUP(L80,'Carton Sizes Chart'!$A$4:$E$15,5,FALSE),0) -> 1.39 | T80: =S80 -> 1.39 | U80: =I80*T80 -> 37.53 | V80: =((T80*I80)-W80)*4% -> 1.42614 | W80: =S80*I80*5% -> 1.8765
A81: 46249 | B81: 46254 | D81: Design ARC Asia | E81: Confidance Knitwear Ltd. | F81: Uniglory Packaging Industries Ltd. | G81: TS02 | H81: 7136184 | I81: 16 | J81: Standard Carton-Singles | K81: BC-Flute | L81: C1 | M81: {=IF(L81="",0,_xlfn.SWITCH(L81,"A1",495,"A2",495,"A3",495,"Custom",0,595))} -> 595 | N81: {=IF(L81="",0,_xlfn.SWITCH(L81,"C1",325,"C2",325,"C3",325,"D1",380,"D2",380,"D3",380,"Custom",0,285))} -> 325 | O81: =IF(L81="",0,_xlfn.SWITCH(L81,"A1",375,"B1",375,"C1",375,"D1",375,"A2",310,"B2",310,"C2",310,"D2",310,"Custom",0,260)) -> 375 | P81: =IFERROR(IF(OR(M81=0,N81=0),0,(M81+N81)*2+11),0) -> 1851 | Q81: =IFERROR(IF(OR(N81=0,O81=0),0,(N81+O81)-16),0) -> 684 | R81: =P81*Q81/1000000 -> 1.266084 | S81: =IFERROR(VLOOKUP(L81,'Carton Sizes Chart'!$A$4:$E$15,5,FALSE),0) -> 1.22 | T81: =S81 -> 1.22 | U81: =I81*T81 -> 19.52 | V81: =((T81*I81)-W81)*4% -> 0.74176 | W81: =S81*I81*5% -> 0.976
A82: 46249 | B82: 46254 | D82: Design ARC Asia | E82: Confidance Knitwear Ltd. | F82: Uniglory Packaging Industries Ltd. | G82: TS02 | H82: 7136184 | I82: 9 | J82: Standard Carton-Singles | K82: BC-Flute | L82: D1 | M82: {=IF(L82="",0,_xlfn.SWITCH(L82,"A1",495,"A2",495,"A3",495,"Custom",0,595))} -> 595 | N82: {=IF(L82="",0,_xlfn.SWITCH(L82,"C1",325,"C2",325,"C3",325,"D1",380,"D2",380,"D3",380,"Custom",0,285))} -> 380 | O82: =IF(L82="",0,_xlfn.SWITCH(L82,"A1",375,"B1",375,"C1",375,"D1",375,"A2",310,"B2",310,"C2",310,"D2",310,"Custom",0,260)) -> 375 | P82: =IFERROR(IF(OR(M82=0,N82=0),0,(M82+N82)*2+11),0) -> 1961 | Q82: =IFERROR(IF(OR(N82=0,O82=0),0,(N82+O82)-16),0) -> 739 | R82: =P82*Q82/1000000 -> 1.449179 | S82: =IFERROR(VLOOKUP(L82,'Carton Sizes Chart'!$A$4:$E$15,5,FALSE),0) -> 1.39 | T82: =S82 -> 1.39 | U82: =I82*T82 -> 12.51 | V82: =((T82*I82)-W82)*4% -> 0.47538 | W82: =S82*I82*5% -> 0.6255
...

Sheet TRACK_CUS
I1: =SUBTOTAL(9,I3:I446) -> 31386 | U1: =SUBTOTAL(9,U3:U446) -> 27383.781 | V1: =SUBTOTAL(9,V3:V446) -> 1848.4052 | W1: =SUBTOTAL(9,W3:W446) -> 2738.3781
A2: PO Received Date | B2: Shipment Date | C2: Matalan Product PO# | D2: Supplier Name | E2: Factory Name | F2: Packaging Supplier Name | G2: eBiz Customer Reference # | H2: eBiz Sales Order # | I2: Carton QTY | J2: Carton Style | K2: FLUTE | L2: Carton Selection | M2: Length(mm) | N2: Width(mm) | O2: Height(mm) | P2: L | Q2: W | R2: Area(sqm) | S2: Carton's Unit Price (CNY,EXW w/VAT) | T2: Final Price, CNY/CTN | U2: Total Amount | V2: 7.5% for PACD | W2: Rebates for Matalan (Ratio&Custom=10%) | X2: NOTE
A3: 46235 | B3: 46237 | D3: KDS IDR Ltd. | E3: KDS IDR Ltd. | F3: Transworld Packaging (BD) Ltd. | G3: B0496925 | H3: 7124457 | I3: 190 | J3: Ratio Carton | K3: C-Flute | L3: R-FPC | M3: {=IFERROR(_xlfn.SWITCH(L3,"R-FPA",495,"R-FPB",595,"R-FPC",595,"R-FPD",595,"Custom Carton","input L"),0)} -> 595 | N3: {=IFERROR(_xlfn.SWITCH(L3,"R-FPA",285,"R-FPB",285,"R-FPC",325,"R-FPD",380,"Custom Carton","input W"),0)} -> 325 | O3: 100 | P3: =IFERROR(IF(K3="",0,(M3+N3)*2+15),0) -> 1855 | Q3: =IFERROR(IF(K3="",0,(N3+O3)-10),0) -> 415 | R3: =P3 * Q3 * (1 + 2.5%) / 1000000 -> 0.78907062 | S3: =R3*'RFQ_Matalan Carton'!$M$32 -> 0.81274274 | T3: =S3 -> 0.81274274 | U3: =I3*T3 -> 154.42112 | V3: =((T3*I3)-W3)*7.5% -> 10.423426 | W3: =S3*I3*10% -> 15.442112
A4: 46235 | B4: 46237 | D4: KDS IDR Ltd. | E4: KDS IDR Ltd. | F4: Transworld Packaging (BD) Ltd. | G4: B0496925 | H4: 7124457 | I4: 190 | J4: Ratio Carton | K4: C-Flute | L4: R-FPC | M4: {=IFERROR(_xlfn.SWITCH(L4,"R-FPA",495,"R-FPB",595,"R-FPC",595,"R-FPD",595,"Custom Carton","input L"),0)} -> 595 | N4: {=IFERROR(_xlfn.SWITCH(L4,"R-FPA",285,"R-FPB",285,"R-FPC",325,"R-FPD",380,"Custom Carton","input W"),0)} -> 325 | O4: 230 | P4: =IFERROR(IF(K4="",0,(M4+N4)*2+15),0) -> 1855 | Q4: =IFERROR(IF(K4="",0,(N4+O4)-10),0) -> 545 | R4: =P4 * Q4 * (1 + 2.5%) / 1000000 -> 1.0362494 | S4: =R4*'RFQ_Matalan Carton'!$M$32 -> 1.0673369 | T4: =S4 -> 1.0673369 | U4: =I4*T4 -> 202.794 | V4: =((T4*I4)-W4)*7.5% -> 13.688595 | W4: =S4*I4*10% -> 20.2794
A5: 46235 | B5: 46237 | D5: KDS IDR Ltd. | E5: KDS IDR Ltd. | F5: Transworld Packaging (BD) Ltd. | G5: G0516728 | H5: 7125716 | I5: 525 | J5: Ratio Carton | K5: C-Flute | L5: R-FPD | M5: {=IFERROR(_xlfn.SWITCH(L5,"R-FPA",495,"R-FPB",595,"R-FPC",595,"R-FPD",595,"Custom Carton","input L"),0)} -> 595 | N5: {=IFERROR(_xlfn.SWITCH(L5,"R-FPA",285,"R-FPB",285,"R-FPC",325,"R-FPD",380,"Custom Carton","input W"),0)} -> 380 | O5: 120 | P5: =IFERROR(IF(K5="",0,(M5+N5)*2+15),0) -> 1965 | Q5: =IFERROR(IF(K5="",0,(N5+O5)-10),0) -> 490 | R5: =P5 * Q5 * (1 + 2.5%) / 1000000 -> 0.98692125 | S5: =R5*'RFQ_Matalan Carton'!$M$32 -> 1.0165289 | T5: =S5 -> 1.0165289 | U5: =I5*T5 -> 533.67767 | V5: =((T5*I5)-W5)*7.5% -> 36.023242 | W5: =S5*I5*10% -> 53.367767
A6: 46233 | B6: 46235 | D6: Design ARC Asia | E6: N.A.Z Bangladesh Ltd. | F6: Transworld Packaging (BD) Ltd. | G6: B0497801 | H6: 7126668 | I6: 338 | J6: Ratio Carton | K6: C-Flute | L6: Custom Carton | M6: 420 | N6: 360 | O6: 100 | P6: =IFERROR(IF(K6="",0,(M6+N6)*2+15),0) -> 1575 | Q6: =IFERROR(IF(K6="",0,(N6+O6)-10),0) -> 450 | R6: =P6 * Q6 * (1 + 2.5%) / 1000000 -> 0.72646875 | S6: =R6*'RFQ_Matalan Carton'!$M$32 -> 0.74826281 | T6: =S6 -> 0.74826281 | U6: =I6*T6 -> 252.91283 | V6: =((T6*I6)-W6)*7.5% -> 17.071616 | W6: =S6*I6*10% -> 25.291283
A7: 46233 | B7: 46235 | D7: Design ARC Asia | E7: N.A.Z Bangladesh Ltd. | F7: Transworld Packaging (BD) Ltd. | G7: B0497801 | H7: 7126668 | I7: 327 | J7: Ratio Carton | K7: C-Flute | L7: Custom Carton | M7: 520 | N7: 400 | O7: 110 | P7: =IFERROR(IF(K7="",0,(M7+N7)*2+15),0) -> 1855 | Q7: =IFERROR(IF(K7="",0,(N7+O7)-10),0) -> 500 | R7: =P7 * Q7 * (1 + 2.5%) / 1000000 -> 0.9506875 | S7: =R7*'RFQ_Matalan Carton'!$M$32 -> 0.97920812 | T7: =S7 -> 0.97920812 | U7: =I7*T7 -> 320.20106 | V7: =((T7*I7)-W7)*7.5% -> 21.613571 | W7: =S7*I7*10% -> 32.020106
A8: 46236 | B8: 46238 | D8: Design ARC Asia | E8: N.A.Z Bangladesh Ltd. | F8: Transworld Packaging (BD) Ltd. | G8: B0493982 | H8: 7127937 | I8: 279 | J8: Ratio Carton | K8: C-Flute | L8: Custom Carton | M8: 420 | N8: 360 | O8: 100 | P8: =IFERROR(IF(K8="",0,(M8+N8)*2+15),0) -> 1575 | Q8: =IFERROR(IF(K8="",0,(N8+O8)-10),0) -> 450 | R8: =P8 * Q8 * (1 + 2.5%) / 1000000 -> 0.72646875 | S8: =R8*'RFQ_Matalan Carton'!$M$32 -> 0.74826281 | T8: =S8 -> 0.74826281 | U8: =I8*T8 -> 208.76532 | V8: =((T8*I8)-W8)*7.5% -> 14.091659 | W8: =S8*I8*10% -> 20.876532
A9: 46236 | B9: 46238 | D9: Design ARC Asia | E9: N.A.Z Bangladesh Ltd. | F9: Transworld Packaging (BD) Ltd. | G9: B0493982 | H9: 7127937 | I9: 279 | J9: Ratio Carton | K9: C-Flute | L9: Custom Carton | M9: 520 | N9: 400 | O9: 120 | P9: =IFERROR(IF(K9="",0,(M9+N9)*2+15),0) -> 1855 | Q9: =IFERROR(IF(K9="",0,(N9+O9)-10),0) -> 510 | R9: =P9 * Q9 * (1 + 2.5%) / 1000000 -> 0.96970125 | S9: =R9*'RFQ_Matalan Carton'!$M$32 -> 0.99879229 | T9: =S9 -> 0.99879229 | U9: =I9*T9 -> 278.66305 | V9: =((T9*I9)-W9)*7.5% -> 18.809756 | W9: =S9*I9*10% -> 27.866305
A10: 46236 | B10: 46238 | D10: Design ARC Asia | E10: N.A.Z Bangladesh Ltd. | F10: Transworld Packaging (BD) Ltd. | G10: B0493982 | H10: 7127937 | I10: 4 | J10: Ratio Carton | K10: C-Flute | L10: Custom Carton | M10: 420 | N10: 300 | O10: 190 | P10: =IFERROR(IF(K10="",0,(M10+N10)*2+15),0) -> 1455 | Q10: =IFERROR(IF(K10="",0,(N10+O10)-10),0) -> 480 | R10: =P10 * Q10 * (1 + 2.5%) / 1000000 -> 0.71586 | S10: =R10*'RFQ_Matalan Carton'!$M$32 -> 0.7373358 | T10: =S10 -> 0.7373358 | U10: =I10*T10 -> 2.9493432 | V10: =((T10*I10)-W10)*7.5% -> 0.19908067 | W10: =S10*I10*10% -> 0.29493432
A11: 46236 | B11: 46238 | D11: Design ARC Asia | E11: N.A.Z Bangladesh Ltd. | F11: Transworld Packaging (BD) Ltd. | G11: B0498084 | H11: 7127940 | I11: 314 | J11: Ratio Carton | K11: C-Flute | L11: Custom Carton | M11: 380 | N11: 300 | O11: 100 | P11: =IFERROR(IF(K11="",0,(M11+N11)*2+15),0) -> 1375 | Q11: =IFERROR(IF(K11="",0,(N11+O11)-10),0) -> 390 | R11: =P11 * Q11 * (1 + 2.5%) / 1000000 -> 0.54965625 | S11: =R11*'RFQ_Matalan Carton'!$M$32 -> 0.56614594 | T11: =S11 -> 0.56614594 | U11: =I11*T11 -> 177.76982 | V11: =((T11*I11)-W11)*7.5% -> 11.999463 | W11: =S11*I11*10% -> 17.776982
A12: 46236 | B12: 46238 | D12: Design ARC Asia | E12: N.A.Z Bangladesh Ltd. | F12: Transworld Packaging (BD) Ltd. | G12: B0498084 | H12: 7127940 | I12: 314 | J12: Ratio Carton | K12: C-Flute | L12: Custom Carton | M12: 420 | N12: 300 | O12: 190 | P12: =IFERROR(IF(K12="",0,(M12+N12)*2+15),0) -> 1455 | Q12: =IFERROR(IF(K12="",0,(N12+O12)-10),0) -> 480 | R12: =P12 * Q12 * (1 + 2.5%) / 1000000 -> 0.71586 | S12: =R12*'RFQ_Matalan Carton'!$M$32 -> 0.7373358 | T12: =S12 -> 0.7373358 | U12: =I12*T12 -> 231.52344 | V12: =((T12*I12)-W12)*7.5% -> 15.627832 | W12: =S12*I12*10% -> 23.152344
A13: 46236 | B13: 46238 | D13: Design ARC Asia | E13: N.A.Z Bangladesh Ltd. | F13: Transworld Packaging (BD) Ltd. | G13: B0498016 | H13: 7127943 | I13: 320 | J13: Ratio Carton | K13: C-Flute | L13: Custom Carton | M13: 300 | N13: 250 | O13: 100 | P13: =IFERROR(IF(K13="",0,(M13+N13)*2+15),0) -> 1115 | Q13: =IFERROR(IF(K13="",0,(N13+O13)-10),0) -> 340 | R13: =P13 * Q13 * (1 + 2.5%) / 1000000 -> 0.3885775 | S13: =R13*'RFQ_Matalan Carton'!$M$32 -> 0.40023482 | T13: =S13 -> 0.40023482 | U13: =I13*T13 -> 128.07514 | V13: =((T13*I13)-W13)*7.5% -> 8.6450722 | W13: =S13*I13*10% -> 12.807514
A14: 46236 | B14: 46238 | D14: Design ARC Asia | E14: N.A.Z Bangladesh Ltd. | F14: Transworld Packaging (BD) Ltd. | G14: B0498016 | H14: 7127943 | I14: 314 | J14: Ratio Carton | K14: C-Flute | L14: Custom Carton | M14: 490 | N14: 300 | O14: 120 | P14: =IFERROR(IF(K14="",0,(M14+N14)*2+15),0) -> 1595 | Q14: =IFERROR(IF(K14="",0,(N14+O14)-10),0) -> 410 | R14: =P14 * Q14 * (1 + 2.5%) / 1000000 -> 0.67029875 | S14: =R14*'RFQ_Matalan Carton'!$M$32 -> 0.69040771 | T14: =S14 -> 0.69040771 | U14: =I14*T14 -> 216.78802 | V14: =((T14*I14)-W14)*7.5% -> 14.633191 | W14: =S14*I14*10% -> 21.678802
A15: 46236 | B15: 46238 | D15: Design ARC Asia | E15: N.A.Z Bangladesh Ltd. | F15: Transworld Packaging (BD) Ltd. | G15: C0992251 | H15: 7127946 | I15: 224 | J15: Ratio Carton | K15: C-Flute | L15: Custom Carton | M15: 460 | N15: 320 | O15: 100 | P15: =IFERROR(IF(K15="",0,(M15+N15)*2+15),0) -> 1575 | Q15: =IFERROR(IF(K15="",0,(N15+O15)-10),0) -> 410 | R15: =P15 * Q15 * (1 + 2.5%) / 1000000 -> 0.66189375 | S15: =R15*'RFQ_Matalan Carton'!$M$32 -> 0.68175056 | T15: =S15 -> 0.68175056 | U15: =I15*T15 -> 152.71213 | V15: =((T15*I15)-W15)*7.5% -> 10.308069 | W15: =S15*I15*10% -> 15.271213
A16: 46236 | B16: 46238 | D16: Design ARC Asia | E16: N.A.Z Bangladesh Ltd. | F16: Transworld Packaging (BD) Ltd. | G16: C0992251 | H16: 7127946 | I16: 224 | J16: Ratio Carton | K16: C-Flute | L16: Custom Carton | M16: 540 | N16: 380 | O16: 100 | P16: =IFERROR(IF(K16="",0,(M16+N16)*2+15),0) -> 1855 | Q16: =IFERROR(IF(K16="",0,(N16+O16)-10),0) -> 470 | R16: =P16 * Q16 * (1 + 2.5%) / 1000000 -> 0.89364625 | S16: =R16*'RFQ_Matalan Carton'!$M$32 -> 0.92045564 | T16: =S16 -> 0.92045564 | U16: =I16*T16 -> 206.18206 | V16: =((T16*I16)-W16)*7.5% -> 13.917289 | W16: =S16*I16*10% -> 20.618206
A17: 46236 | B17: 46238 | D17: Design ARC Asia | E17: N.A.Z Bangladesh Ltd. | F17: Transworld Packaging (BD) Ltd. | G17: C1002485 | H17: 7127949 | I17: 130 | J17: Ratio Carton | K17: C-Flute | L17: Custom Carton | M17: 420 | N17: 350 | O17: 100 | P17: =IFERROR(IF(K17="",0,(M17+N17)*2+15),0) -> 1555 | Q17: =IFERROR(IF(K17="",0,(N17+O17)-10),0) -> 440 | R17: =P17 * Q17 * (1 + 2.5%) / 1000000 -> 0.701305 | S17: =R17*'RFQ_Matalan Carton'!$M$32 -> 0.72234415 | T17: =S17 -> 0.72234415 | U17: =I17*T17 -> 93.904739 | V17: =((T17*I17)-W17)*7.5% -> 6.3385699 | W17: =S17*I17*10% -> 9.3904739
A18: 46236 | B18: 46238 | D18: Design ARC Asia | E18: N.A.Z Bangladesh Ltd. | F18: Transworld Packaging (BD) Ltd. | G18: C1002485 | H18: 7127949 | I18: 125 | J18: Ratio Carton | K18: C-Flute | L18: Custom Carton | M18: 450 | N18: 380 | O18: 140 | P18: =IFERROR(IF(K18="",0,(M18+N18)*2+15),0) -> 1675 | Q18: =IFERROR(IF(K18="",0,(N18+O18)-10),0) -> 510 | R18: =P18 * Q18 * (1 + 2.5%) / 1000000 -> 0.87560625 | S18: =R18*'RFQ_Matalan Carton'!$M$32 -> 0.90187444 | T18: =S18 -> 0.90187444 | U18: =I18*T18 -> 112.7343 | V18: =((T18*I18)-W18)*7.5% -> 7.6095656 | W18: =S18*I18*10% -> 11.27343
A19: 46240 | B19: 46243 | D19: KDS IDR Ltd. | E19: KDS IDR Ltd. | F19: Transworld Packaging (BD) Ltd. | G19: G0516742 | H19: 7130655 | I19: 145 | J19: Ratio Carton | K19: C-Flute | L19: R-FPD | M19: {=IFERROR(_xlfn.SWITCH(L19,"R-FPA",495,"R-FPB",595,"R-FPC",595,"R-FPD",595,"Custom Carton","input L"),0)} -> 595 | N19: {=IFERROR(_xlfn.SWITCH(L19,"R-FPA",285,"R-FPB",285,"R-FPC",325,"R-FPD",380,"Custom Carton","input W"),0)} -> 380 | O19: 180 | P19: =IFERROR(IF(K19="",0,(M19+N19)*2+15),0) -> 1965 | Q19: =IFERROR(IF(K19="",0,(N19+O19)-10),0) -> 550 | R19: =P19 * Q19 * (1 + 2.5%) / 1000000 -> 1.1077687 | S19: =R19*'RFQ_Matalan Carton'!$M$32 -> 1.1410018 | T19: =S19 -> 1.1410018 | U19: =I19*T19 -> 165.44526 | V19: =((T19*I19)-W19)*7.5% -> 11.167555 | W19: =S19*I19*10% -> 16.544526
A20: 46240 | B20: 46243 | D20: KDS IDR Ltd. | E20: KDS IDR Ltd. | F20: Transworld Packaging (BD) Ltd. | G20: G0516742 | H20: 7130655 | I20: 145 | J20: Ratio Carton | K20: C-Flute | L20: R-FPD | M20: {=IFERROR(_xlfn.SWITCH(L20,"R-FPA",495,"R-FPB",595,"R-FPC",595,"R-FPD",595,"Custom Carton","input L"),0)} -> 595 | N20: {=IFERROR(_xlfn.SWITCH(L20,"R-FPA",285,"R-FPB",285,"R-FPC",325,"R-FPD",380,"Custom Carton","input W"),0)} -> 380 | O20: 220 | P20: =IFERROR(IF(K20="",0,(M20+N20)*2+15),0) -> 1965 | Q20: =IFERROR(IF(K20="",0,(N20+O20)-10),0) -> 590 | R20: =P20 * Q20 * (1 + 2.5%) / 1000000 -> 1.1883337 | S20: =R20*'RFQ_Matalan Carton'!$M$32 -> 1.2239838 | T20: =S20 -> 1.2239838 | U20: =I20*T20 -> 177.47765 | V20: =((T20*I20)-W20)*7.5% -> 11.979741 | W20: =S20*I20*10% -> 17.747765
A21: 46240 | B21: 46243 | D21: KDS IDR Ltd. | E21: KDS IDR Ltd. | F21: Transworld Packaging (BD) Ltd. | G21: C0989744 | H21: 7131103 | I21: 15 | J21: Ratio Carton | K21: C-Flute | L21: R-FPD | M21: {=IFERROR(_xlfn.SWITCH(L21,"R-FPA",495,"R-FPB",595,"R-FPC",595,"R-FPD",595,"Custom Carton","input L"),0)} -> 595 | N21: {=IFERROR(_xlfn.SWITCH(L21,"R-FPA",285,"R-FPB",285,"R-FPC",325,"R-FPD",380,"Custom Carton","input W"),0)} -> 380 | O21: 300 | P21: =IFERROR(IF(K21="",0,(M21+N21)*2+15),0) -> 1965 | Q21: =IFERROR(IF(K21="",0,(N21+O21)-10),0) -> 670 | R21: =P21 * Q21 * (1 + 2.5%) / 1000000 -> 1.3494637 | S21: =R21*'RFQ_Matalan Carton'!$M$32 -> 1.3899477 | T21: =S21 -> 1.3899477 | U21: =I21*T21 -> 20.849215 | V21: =((T21*I21)-W21)*7.5% -> 1.407322 | W21: =S21*I21*10% -> 2.0849215
A22: 46243 | B22: 46244 | D22: Design ARC Asia | E22: N.A.Z Bangladesh Ltd. | F22: Transworld Packaging (BD) Ltd. | G22: DHW6LBF031 | H22: 7132164 | I22: 317 | J22: Ratio Carton | K22: C-Flute | L22: Custom Carton | M22: 390 | N22: 350 | O22: 100 | P22: =IFERROR(IF(K22="",0,(M22+N22)*2+15),0) -> 1495 | Q22: =IFERROR(IF(K22="",0,(N22+O22)-10),0) -> 440 | R22: =P22 * Q22 * (1 + 2.5%) / 1000000 -> 0.674245 | S22: =R22*'RFQ_Matalan Carton'!$M$32 -> 0.69447235 | T22: =S22 -> 0.69447235 | U22: =I22*T22 -> 220.14773 | V22: =((T22*I22)-W22)*7.5% -> 14.859972 | W22: =S22*I22*10% -> 22.014773
A23: 46243 | B23: 46244 | D23: Design ARC Asia | E23: N.A.Z Bangladesh Ltd. | F23: Transworld Packaging (BD) Ltd. | G23: DHW6LBF031 | H23: 7132164 | I23: 317 | J23: Ratio Carton | K23: C-Flute | L23: Custom Carton | M23: 420 | N23: 370 | O23: 100 | P23: =IFERROR(IF(K23="",0,(M23+N23)*2+15),0) -> 1595 | Q23: =IFERROR(IF(K23="",0,(N23+O23)-10),0) -> 460 | R23: =P23 * Q23 * (1 + 2.5%) / 1000000 -> 0.7520425 | S23: =R23*'RFQ_Matalan Carton'!$M$32 -> 0.77460377 | T23: =S23 -> 0.77460377 | U23: =I23*T23 -> 245.5494 | V23: =((T23*I23)-W23)*7.5% -> 16.574584 | W23: =S23*I23*10% -> 24.55494
A24: 46243 | B24: 46244 | D24: Design ARC Asia | E24: N.A.Z Bangladesh Ltd. | F24: Transworld Packaging (BD) Ltd. | G24: DHW6LBF031 | H24: 7132164 | I24: 317 | J24: Ratio Carton | K24: C-Flute | L24: Custom Carton | M24: 480 | N24: 430 | O24: 100 | P24: =IFERROR(IF(K24="",0,(M24+N24)*2+15),0) -> 1835 | Q24: =IFERROR(IF(K24="",0,(N24+O24)-10),0) -> 520 | R24: =P24 * Q24 * (1 + 2.5%) / 1000000 -> 0.978055 | S24: =R24*'RFQ_Matalan Carton'!$M$32 -> 1.0073967 | T24: =S24 -> 1.0073967 | U24: =I24*T24 -> 319.34474 | V24: =((T24*I24)-W24)*7.5% -> 21.55577 | W24: =S24*I24*10% -> 31.934474
A25: 46245 | B25: 46247 | D25: Design ARC Asia | E25: N.A.Z Bangladesh Ltd. | F25: Transworld Packaging (BD) Ltd. | G25: DHW6DBF21A | H25: 7132915 | I25: 324 | J25: Ratio Carton | K25: C-Flute | L25: Custom Carton | M25: 400 | N25: 360 | O25: 100 | P25: =IFERROR(IF(K25="",0,(M25+N25)*2+15),0) -> 1535 | Q25: =IFERROR(IF(K25="",0,(N25+O25)-10),0) -> 450 | R25: =P25 * Q25 * (1 + 2.5%) / 1000000 -> 0.70801875 | S25: =R25*'RFQ_Matalan Carton'!$M$32 -> 0.72925931 | T25: =S25 -> 0.72925931 | U25: =I25*T25 -> 236.28002 | V25: =((T25*I25)-W25)*7.5% -> 15.948901 | W25: =S25*I25*10% -> 23.628002
A26: 46245 | B26: 46247 | D26: Design ARC Asia | E26: N.A.Z Bangladesh Ltd. | F26: Transworld Packaging (BD) Ltd. | G26: DHW6DBF21A | H26: 7132915 | I26: 323 | J26: Ratio Carton | K26: C-Flute | L26: Custom Carton | M26: 460 | N26: 420 | O26: 210 | P26: =IFERROR(IF(K26="",0,(M26+N26)*2+15),0) -> 1775 | Q26: =IFERROR(IF(K26="",0,(N26+O26)-10),0) -> 620 | R26: =P26 * Q26 * (1 + 2.5%) / 1000000 -> 1.1280125 | S26: =R26*'RFQ_Matalan Carton'!$M$32 -> 1.1618529 | T26: =S26 -> 1.1618529 | U26: =I26*T26 -> 375.27848 | V26: =((T26*I26)-W26)*7.5% -> 25.331297 | W26: =S26*I26*10% -> 37.527848
A27: 46245 | B27: 46247 | D27: Design ARC Asia | E27: N.A.Z Bangladesh Ltd. | F27: Transworld Packaging (BD) Ltd. | G27: SPS26BT02 | H27: 7132933 | I27: 299 | J27: Ratio Carton | K27: C-Flute | L27: Custom Carton | M27: 460 | N27: 420 | O27: 100 | P27: =IFERROR(IF(K27="",0,(M27+N27)*2+15),0) -> 1775 | Q27: =IFERROR(IF(K27="",0,(N27+O27)-10),0) -> 510 | R27: =P27 * Q27 * (1 + 2.5%) / 1000000 -> 0.92788125 | S27: =R27*'RFQ_Matalan Carton'!$M$32 -> 0.95571769 | T27: =S27 -> 0.95571769 | U27: =I27*T27 -> 285.75959 | V27: =((T27*I27)-W27)*7.5% -> 19.288772 | W27: =S27*I27*10% -> 28.575959
A28: 46245 | B28: 46247 | D28: Design ARC Asia | E28: N.A.Z Bangladesh Ltd. | F28: Transworld Packaging (BD) Ltd. | G28: SPS26BT02 | H28: 7132933 | I28: 293 | J28: Ratio Carton | K28: C-Flute | L28: Custom Carton | M28: 500 | N28: 420 | O28: 120 | P28: =IFERROR(IF(K28="",0,(M28+N28)*2+15),0) -> 1855 | Q28: =IFERROR(IF(K28="",0,(N28+O28)-10),0) -> 530 | R28: =P28 * Q28 * (1 + 2.5%) / 1000000 -> 1.0077287 | S28: =R28*'RFQ_Matalan Carton'!$M$32 -> 1.0379606 | T28: =S28 -> 1.0379606 | U28: =I28*T28 -> 304.12246 | V28: =((T28*I28)-W28)*7.5% -> 20.528266 | W28: =S28*I28*10% -> 30.412246
A29: 46247 | B29: 46249 | D29: Design ARC Asia | E29: N.A.Z Bangladesh Ltd. | F29: Transworld Packaging (BD) Ltd. | G29: GCW265TS04A | H29: 7134055 | I29: 301 | J29: Ratio Carton | K29: C-Flute | L29: Custom Carton | M29: 400 | N29: 300 | O29: 100 | P29: =IFERROR(IF(K29="",0,(M29+N29)*2+15),0) -> 1415 | Q29: =IFERROR(IF(K29="",0,(N29+O29)-10),0) -> 390 | R29: =P29 * Q29 * (1 + 2.5%) / 1000000 -> 0.56564625 | S29: =R29*'RFQ_Matalan Carton'!$M$32 -> 0.58261564 | T29: =S29 -> 0.58261564 | U29: =I29*T29 -> 175.36731 | V29: =((T29*I29)-W29)*7.5% -> 11.837293 | W29: =S29*I29*10% -> 17.536731
A30: 46247 | B30: 46249 | D30: Design ARC Asia | E30: N.A.Z Bangladesh Ltd. | F30: Transworld Packaging (BD) Ltd. | G30: GCW265TS04A | H30: 7134055 | I30: 301 | J30: Ratio Carton | K30: C-Flute | L30: Custom Carton | M30: 420 | N30: 360 | O30: 220 | P30: =IFERROR(IF(K30="",0,(M30+N30)*2+15),0) -> 1575 | Q30: =IFERROR(IF(K30="",0,(N30+O30)-10),0) -> 570 | R30: =P30 * Q30 * (1 + 2.5%) / 1000000 -> 0.92019375 | S30: =R30*'RFQ_Matalan Carton'!$M$32 -> 0.94779956 | T30: =S30 -> 0.94779956 | U30: =I30*T30 -> 285.28767 | V30: =((T30*I30)-W30)*7.5% -> 19.256918 | W30: =S30*I30*10% -> 28.528767
A31: 46247 | B31: 46249 | D31: Design ARC Asia | E31: N.A.Z Bangladesh Ltd. | F31: Transworld Packaging (BD) Ltd. | G31: DHW6DBF22A | H31: 7134646 | I31: 320 | J31: Ratio Carton | K31: C-Flute | L31: Custom Carton | M31: 380 | N31: 260 | O31: 100 | P31: =IFERROR(IF(K31="",0,(M31+N31)*2+15),0) -> 1295 | Q31: =IFERROR(IF(K31="",0,(N31+O31)-10),0) -> 350 | R31: =P31 * Q31 * (1 + 2.5%) / 1000000 -> 0.46458125 | S31: =R31*'RFQ_Matalan Carton'!$M$32 -> 0.47851869 | T31: =S31 -> 0.47851869 | U31: =I31*T31 -> 153.12598 | V31: =((T31*I31)-W31)*7.5% -> 10.336004 | W31: =S31*I31*10% -> 15.312598
A32: 46247 | B32: 46249 | D32: Design ARC Asia | E32: N.A.Z Bangladesh Ltd. | F32: Transworld Packaging (BD) Ltd. | G32: DHW6DBF22A | H32: 7134646 | I32: 320 | J32: Ratio Carton | K32: C-Flute | L32: Custom Carton | M32: 440 | N32: 330 | O32: 120 | P32: =IFERROR(IF(K32="",0,(M32+N32)*2+15),0) -> 1555 | Q32: =IFERROR(IF(K32="",0,(N32+O32)-10),0) -> 440 | R32: =P32 * Q32 * (1 + 2.5%) / 1000000 -> 0.701305 | S32: =R32*'RFQ_Matalan Carton'!$M$32 -> 0.72234415 | T32: =S32 -> 0.72234415 | U32: =I32*T32 -> 231.15013 | V32: =((T32*I32)-W32)*7.5% -> 15.602634 | W32: =S32*I32*10% -> 23.115013
A33: 46247 | B33: 46249 | D33: Design ARC Asia | E33: N.A.Z Bangladesh Ltd. | F33: Transworld Packaging (BD) Ltd. | G33: GCW25TS04A | H33: 7134668 | I33: 279 | J33: Ratio Carton | K33: C-Flute | L33: Custom Carton | M33: 300 | N33: 250 | O33: 100 | P33: =IFERROR(IF(K33="",0,(M33+N33)*2+15),0) -> 1115 | Q33: =IFERROR(IF(K33="",0,(N33+O33)-10),0) -> 340 | R33: =P33 * Q33 * (1 + 2.5%) / 1000000 -> 0.3885775 | S33: =R33*'RFQ_Matalan Carton'!$M$32 -> 0.40023482 | T33: =S33 -> 0.40023482 | U33: =I33*T33 -> 111.66552 | V33: =((T33*I33)-W33)*7.5% -> 7.5374223 | W33: =S33*I33*10% -> 11.166552
... A36: 46247 | B36: 46249 | D36: Design ARC Asia | E36: N.A.Z Bangladesh Ltd. | F36: Transworld Packaging (BD) Ltd. | G36: GCW26SE20A | H36: 7134857 | I36: 271 | J36: Ratio Carton | K36: C-Flute | L36: Custom Carton | M36: 500 | N36: 420 | O36: 230 | P36: =IFERROR(IF(K36="",0,(M36+N36)*2+15),0) -> 1855 | Q36: =IFERROR(IF(K36="",0,(N36+O36)-10),0) -> 640 | R36: =P36 * Q36 * (1 + 2.5%) / 1000000 -> 1.21688 | S36: =R36*'RFQ_Matalan Carton'!$M$32 -> 1.2533864 | T36: =S36 -> 1.2533864 | U36: =I36*T36 -> 339.66771 | V36: =((T36*I36)-W36)*7.5% -> 22.927571 | W36: =S36*I36*10% -> 33.966771
A37: 46250 | B37: 46251 | D37: KDS IDR Ltd. | E37: KDS IDR Ltd. | F37: Transworld Packaging (BD) Ltd. | G37: B0494456 | H37: 7135559 | I37: 290 | J37: Ratio Carton | K37: C-Flute | L37: R-FPD | M37: {=IFERROR(_xlfn.SWITCH(L37,"R-FPA",495,"R-FPB",595,"R-FPC",595,"R-FPD",595,"Custom Carton","input L"),0)} -> 595 | N37: {=IFERROR(_xlfn.SWITCH(L37,"R-FPA",285,"R-FPB",285,"R-FPC",325,"R-FPD",380,"Custom Carton","input W"),0)} -> 380 | O37: 100 | P37: =IFERROR(IF(K37="",0,(M37+N37)*2+15),0) -> 1965 | Q37: =IFERROR(IF(K37="",0,(N37+O37)-10),0) -> 470 | R37: =P37 * Q37 * (1 + 2.5%) / 1000000 -> 0.94663875 | S37: =R37*'RFQ_Matalan Carton'!$M$32 -> 0.97503791 | T37: =S37 -> 0.97503791 | U37: =I37*T37 -> 282.76099 | V37: =((T37*I37)-W37)*7.5% -> 19.086367 | W37: =S37*I37*10% -> 28.276099
A38: 46250 | B38: 46251 | D38: KDS IDR Ltd. | E38: KDS IDR Ltd. | F38: Transworld Packaging (BD) Ltd. | G38: B0494456 | H38: 7135559 | I38: 290 | J38: Ratio Carton | K38: C-Flute | L38: R-FPD | M38: {=IFERROR(_xlfn.SWITCH(L38,"R-FPA",495,"R-FPB",595,"R-FPC",595,"R-FPD",595,"Custom Carton","input L"),0)} -> 595 | N38: {=IFERROR(_xlfn.SWITCH(L38,"R-FPA",285,"R-FPB",285,"R-FPC",325,"R-FPD",380,"Custom Carton","input W"),0)} -> 380 | O38: 220 | P38: =IFERROR(IF(K38="",0,(M38+N38)*2+15),0) -> 1965 | Q38: =IFERROR(IF(K38="",0,(N38+O38)-10),0) -> 590 | R38: =P38 * Q38 * (1 + 2.5%) / 1000000 -> 1.1883337 | S38: =R38*'RFQ_Matalan Carton'!$M$32 -> 1.2239838 | T38: =S38 -> 1.2239838 | U38: =I38*T38 -> 354.95529 | V38: =((T38*I38)-W38)*7.5% -> 23.959482 | W38: =S38*I38*10% -> 35.495529
A39: 46250 | B39: 46251 | D39: KDS IDR Ltd. | E39: KDS IDR Ltd. | F39: Transworld Packaging (BD) Ltd. | G39: B0498208 | H39: 7135563 | I39: 310 | J39: Ratio Carton | K39: C-Flute | L39: R-FPC | M39: {=IFERROR(_xlfn.SWITCH(L39,"R-FPA",495,"R-FPB",595,"R-FPC",595,"R-FPD",595,"Custom Carton","input L"),0)} -> 595 | N39: {=IFERROR(_xlfn.SWITCH(L39,"R-FPA",285,"R-FPB",285,"R-FPC",325,"R-FPD",380,"Custom Carton","input W"),0)} -> 325 | O39: 100 | P39: =IFERROR(IF(K39="",0,(M39+N39)*2+15),0) -> 1855 | Q39: =IFERROR(IF(K39="",0,(N39+O39)-10),0) -> 415 | R39: =P39 * Q39 * (1 + 2.5%) / 1000000 -> 0.78907062 | S39: =R39*'RFQ_Matalan Carton'!$M$32 -> 0.81274274 | T39: =S39 -> 0.81274274 | U39: =I39*T39 -> 251.95025 | V39: =((T39*I39)-W39)*7.5% -> 17.006642 | W39: =S39*I39*10% -> 25.195025
A40: 46250 | B40: 46251 | D40: KDS IDR Ltd. | E40: KDS IDR Ltd. | F40: Transworld Packaging (BD) Ltd. | G40: B0498208 | H40: 7135563 | I40: 310 | J40: Ratio Carton | K40: C-Flute | L40: R-FPC | M40: {=IFERROR(_xlfn.SWITCH(L40,"R-FPA",495,"R-FPB",595,"R-FPC",595,"R-FPD",595,"Custom Carton","input L"),0)} -> 595 | N40: {=IFERROR(_xlfn.SWITCH(L40,"R-FPA",285,"R-FPB",285,"R-FPC",325,"R-FPD",380,"Custom Carton","input W"),0)} -> 325 | O40: 270 | P40: =IFERROR(IF(K40="",0,(M40+N40)*2+15),0) -> 1855 | Q40: =IFERROR(IF(K40="",0,(N40+O40)-10),0) -> 585 | R40: =P40 * Q40 * (1 + 2.5%) / 1000000 -> 1.1123044 | S40: =R40*'RFQ_Matalan Carton'!$M$32 -> 1.1456735 | T40: =S40 -> 1.1456735 | U40: =I40*T40 -> 355.15879 | V40: =((T40*I40)-W40)*7.5% -> 23.973218 | W40: =S40*I40*10% -> 35.515879
A41: 46250 | B41: 46251 | D41: KDS IDR Ltd. | E41: KDS IDR Ltd. | F41: Transworld Packaging (BD) Ltd. | G41: C0990206 | H41: 7135574 | I41: 300 | J41: Ratio Carton | K41: C-Flute | L41: R-FPC | M41: {=IFERROR(_xlfn.SWITCH(L41,"R-FPA",495,"R-FPB",595,"R-FPC",595,"R-FPD",595,"Custom Carton","input L"),0)} -> 595 | N41: {=IFERROR(_xlfn.SWITCH(L41,"R-FPA",285,"R-FPB",285,"R-FPC",325,"R-FPD",380,"Custom Carton","input W"),0)} -> 325 | O41: 100 | P41: =IFERROR(IF(K41="",0,(M41+N41)*2+15),0) -> 1855 | Q41: =IFERROR(IF(K41="",0,(N41+O41)-10),0) -> 415 | R41: =P41 * Q41 * (1 + 2.5%) / 1000000 -> 0.78907062 | S41: =R41*'RFQ_Matalan Carton'!$M$32 -> 0.81274274 | T41: =S41 -> 0.81274274 | U41: =I41*T41 -> 243.82282 | V41: =((T41*I41)-W41)*7.5% -> 16.458041 | W41: =S41*I41*10% -> 24.382282
A42: 46250 | B42: 46251 | D42: KDS IDR Ltd. | E42: KDS IDR Ltd. | F42: Transworld Packaging (BD) Ltd. | G42: C0990206 | H42: 7135574 | I42: 300 | J42: Ratio Carton | K42: C-Flute | L42: R-FPC | M42: {=IFERROR(_xlfn.SWITCH(L42,"R-FPA",495,"R-FPB",595,"R-FPC",595,"R-FPD",595,"Custom Carton","input L"),0)} -> 595 | N42: {=IFERROR(_xlfn.SWITCH(L42,"R-FPA",285,"R-FPB",285,"R-FPC",325,"R-FPD",380,"Custom Carton","input W"),0)} -> 325 | O42: 240 | P42: =IFERROR(IF(K42="",0,(M42+N42)*2+15),0) -> 1855 | Q42: =IFERROR(IF(K42="",0,(N42+O42)-10),0) -> 555 | R42: =P42 * Q42 * (1 + 2.5%) / 1000000 -> 1.0552631 | S42: =R42*'RFQ_Matalan Carton'!$M$32 -> 1.086921 | T42: =S42 -> 1.086921 | U42: =I42*T42 -> 326.07631 | V42: =((T42*I42)-W42)*7.5% -> 22.010151 | W42: =S42*I42*10% -> 32.607631
...

Sheet RFQ_Matalan Carton
A1: MATALAN SHIPPING CARTON RFQ | J1: Version: 1.2 | K1: 45968
A4: Quoted by: | B4: Bangladesh Estimated prices, but need to confirm with Pkg Suppliers | G4: NOTE:
A5: Supply to: | B5: Matalan Product Factories | G5: 1- Standard cartons from A1~D3 need to be quoted by each
A6: Delivery: | B6: EX-Works | G6: 2- The Price Calculator only for custom carton in RSC(Regular Slotted Carton, FEFCO-0201) style
A7: Payments | B7: Net 45 Days (end of month invoicing) | G7: 3- The results is EX-Works price with MOQ>=100pcs, (MOQ=Minimum Order Quantity)
A8: VAT: | B8: Included | G8: 4- Packaging Factory will charge a $20 fee for PO quantity less than MOQ=100; If printing is different on any line item, that is considered a unique PO quantity.
A9: MOQ/MDQ: | B9: 100
A10: Drawings: | B10: Attached Matalan standard carton drawings | G10: 5- Price rate will be reviewed every six months. Pricing to be advised no less than 30 days prior to the next 6 month term.
A11: Date: | B11: 46023
A13: STANDARD CARTON
A14: CTN# | B14: CARTON OUTSIDE DIMENSION(mm) | E14: CARTON STYLE | F14: PRINTING | G14: FLUTE TYPE | H14: ECT(lbs/in) | I14: BLANK SIZE(mm) | K14: AREA(sqm) | L14: MOQ | M14: EXW Price
